Workbook

Sheet Overview
A1: NEO Mathematics Curriculum Vault Map — Pathways v0.2
A2: A navigable curriculum organised by pathway, internal stage, mathematical strand, inquiry, Cornerstones, learner-owned evidence, Mastery and qualification overlays.
A4: Curriculum KPI | B4: Value | D4: Pathway | E4: Unit Count | F4: % of Map | G4: Curriculum Role | H4: How to Use This Workbook
A5: Mapped units | B5: =COUNTA('Curriculum Map'!A5:A72) -> 68 | D5: Foundations | E5: 48 | F5: 0.70588235 | G5: Entry, reconnection, core relationships and applied routes | H5: 1 | I5: Curriculum Map | J5: Filter by Pathway, Strand, Cornerstone or Build Status.
A6: Canonical Stepping Stones | B6: =COUNTA('Stepping Stones'!A5:A399) -> 395 | D6: Intermediate | E6: 20 | F6: 0.29411765 | G6: IGCSE canonical spine, synthesis and qualification navigation | H6: 2 | I6: Stepping Stones | J6: Use the unique IDs as canonical curriculum nodes and evidence tags.
A7: Qualification overlay links | B7: =COUNTA('Qualification Overlays'!A5:A114) -> 110 | D7: Advanced | E7: 0 | F7: 0 | G7: Future A-Level pathway; not yet mapped | H7: 3 | I7: Qualification Overlays | J7: Audit how NC KS3, 4MA1 and Functional Skills assess canonical learning.
A8: Locked reference prototypes | B8: =COUNTIF('Build Tracker'!L5:L72,"Locked prototype") -> 2 | H8: 4 | I8: Cornerstone Map | J8: Audit design fit and check that Nutrition is not being forced.
H9: 5 | I9: Interactive Tools | J9: Prioritise reusable tool families before authoring 68 separate apps.
H10: 6 | I10: Portfolio & Mastery | J10: Attach learner-owned evidence and outcome-level Mastery judgements.
A11: Locked Architecture | D11: Functional & Applied Mathematics | E11: =COUNTIF('Curriculum Map'!$B$5:$B$72,D11) -> 0 | F11: =E11/$B$5 -> 0 | G11: Practical route alongside or towards iGCSE | H11: 7 | I11: Build Tracker | J11: Move each unit from map → tool → HTML → guides → review → lock.
A12: Curriculum Spine × Overlay | B12: Canonical NEO mathematics is taught first; external specifications map onto it. | H12: 8 | I12: Sources & Notes | J12: Check authority, URLs, assumptions and annual-review triggers.
A13: Stepping Stones | B13: Learner-facing progression language and canonical outcome nodes.
A14: Cornerstones | B14: Connection, Movement, Creativity, Reflection, Rest and Nutrition as design lenses. | D14: Primary Cornerstone | E14: Mapped Units | F14: Design Note
A15: Inquiry rhythm | B15: Predict → Sketch → Test → Notice → Revise. | D15: Connection | E15: ='Cornerstone Map'!B5 -> 22 | F15: Make mathematical relationships and human dialogue visible.
A16: Lesson package | B16: Interactive Lesson + Practice Companion + Final Portfolio Task + Learner Guide + Supporting Adult Guidance. | D16: Movement | E16: ='Cornerstone Map'!B6 -> 14 | F16: Treat mathematical ideas as dynamic; trace change or movement.
A17: Scratchpad | B17: Embedded in-page NEO Maths Scratchpad; no external whiteboard URL required. | D17: Creativity | E17: ='Cornerstone Map'!B7 -> 10 | F17: Invite conjecture, multiple routes, making and model-building.
A18: Mastery | B18: Emerging → Developing → Secure → Mastering, judged per outcome demonstration. | D18: Reflection | E18: ='Cornerstone Map'!B8 -> 19 | F18: Surface reasoning, misconceptions, proof and metacognition.
D19: Rest | E19: ='Cornerstone Map'!B9 -> 3 | F19: Chunk, regulate sensory load and protect the right to pause.
D20: Nutrition | E20: ='Cornerstone Map'!B10 -> 0 | F20: Use food/body/health/sustainability contexts only where genuine.

Sheet Curriculum Map
A1: NEO Mathematics Curriculum Map — Pathways
A2: Canonical Curriculum Spine × Qualification Overlay. Pathway is learner-facing; Internal Stage remains planning metadata.
A4: Unit ID | B4: Pathway | C4: Internal Stage | D4: Sequence | E4: Mathematical Strand | F4: Unit Title | G4: Driving Question | H4: Stepping Stones | I4: Primary Cornerstone | J4: Secondary Cornerstone(s) | K4: Cornerstone Fit | L4: Interactive Inquiry Tool | M4: Scratchpad Template | N4: Portfolio Evidence | O4: Qualification Overlay | P4: Overlay Reference | Q4: Suggested Mode(s) | R4: Sensory / Cognitive Load | S4: Prerequisite Connections | T4: Next Connections | U4: Current Status | V4: Curriculum Design Note | W4: Evidence / Live Count | X4: GreenPrint Version
A5: NEO-MATH-DISC-01 | B5: Foundations | C5: Flexible entry | D5: 1 | E5: Self-Regulated Mathematical Learning | F5: Finding My Maths Starting Point | G5: What happens when maths begins with what I already notice? | H5: notice mathematical strengths; try different representations; use support tools; explain what helps; choose a next Stepping Stone | I5: Connection | J5: Reflection, Rest | K5: Strong | L5: Maths Route Finder: visual, numerical and contextual mini-challenges | M5: Blank / Square grid | N5: My Maths Map: strengths, supports and next steps | O5: NEO canonical; diagnostic bridge | P5: Not an awarding-body unit; informs pathway entry | Q5: Live, Asynchronous, Independent | R5: Low; choice-rich, no timed score | S5: None | T5: Place value; calculation; FDP; applied routes | U5: Mapped / not yet built | V5: Canonical unit; lesson sequence to be authored from mapped Stepping Stones. | W5: Curriculum map evidence only | X5: GreenPrint v1.1 / map v0.2
A6: NEO-MATH-DISC-02 | B6: Foundations | C6: Flexible entry | D6: 2 | E6: Number Sense | F6: Numbers I Can Trust | G6: How can I make a number less crowded? | H6: read and compare integers and decimals; use place value; locate zero; estimate; check reasonableness | I6: Rest | J6: Connection, Reflection | K6: Strong | L6: Place-Value Magnifier and Number Line Zoom | M6: Square grid | N6: Annotated Number Confidence Card | O6: NC KS3 Number; FS L1/L2 | P6: NC KS3 Number; FS L1 1-3,10-12; FS L2 1-2,9-10 | Q6: Live, Asynchronous, Independent | R6: Low-Moderate; one digit/interval at a time | S6: Maths Route Finder | T6: Operations and equivalence | U6: Prototype — header update required | V6: Canonical unit; lesson sequence to be authored from mapped Stepping Stones. | W6: Place Value migrated v0.6 + two guidance PDFs | X6: GreenPrint v1.1 / map v0.2
A7: NEO-MATH-DISC-03 | B7: Foundations | C7: Flexible entry | D7: 3 | E7: Number Sense | F7: Operations as Choices | G7: Is there more than one sensible way to calculate? | H7: select a calculation strategy; use inverse operations; follow operation order; estimate first; explain a method choice | I7: Creativity | J7: Reflection, Rest | K7: Strong | L7: Strategy Switcher: compare mental, written and calculator routes | M7: Blank | N7: My Best Method Guide | O7: NC KS3 Working Mathematically; FS L1/L2 | P7: NC KS3 fluency/problem solving; FS L1 4,7,15; FS L2 2,12 | Q7: Live, Asynchronous, Independent | R7: Moderate; method menu reduces overload | S7: Place value | T7: Fractions, percentages and algebra | U7: Mapped / not yet built | V7: Canonical unit; lesson sequence to be authored from mapped Stepping Stones. | W7: Curriculum map evidence only | X7: GreenPrint v1.1 / map v0.2
A8: NEO-MATH-DISC-04 | B8: Foundations | C8: Flexible entry | D8: 4 | E8: Proportional Reasoning | F8: Fractions, Decimals and Percentages as One Family | G8: Can three different-looking numbers mean the same amount? | H8: recognise common equivalences; compare FDP; convert representations; find fractions and percentages of quantities; choose a helpful representation | I8: Connection | J8: Creativity, Reflection | K8: Strong | L8: FDP Representation Carousel | M8: Double number line | N8: Equivalence Gallery | O8: NC KS3 Number/Ratio; FS L1/L2 | P8: NC KS3 Number and Ratio; FS L1 8-17; FS L2 4-10 | Q8: Live, Asynchronous, Independent | R8: Moderate; representation choice | S8: Operations | T8: Ratio and percentage change | U8: Mapped / not yet built | V8: Canonical unit; lesson sequence to be authored from mapped Stepping Stones. | W8: Curriculum map evidence only | X8: GreenPrint v1.1 / map v0.2
A9: NEO-MATH-DISC-05 | B9: Foundations | C9: Flexible entry | D9: 5 | E9: Structure & Generalisation | F9: Patterns Before Letters | G9: Can a pattern explain itself before we use algebra? | H9: continue sequences; describe a rule; use a variable; substitute values; create and test a conjecture | I9: Creativity | J9: Connection, Reflection | K9: Strong | L9: Pattern Machine and Rule Builder | M9: Square grid | N9: Pattern Rule Card with examples and non-examples | O9: NC KS3 Algebra; FS L1/L2 bridge | P9: NC KS3 Algebra; FS L1 5; FS L2 3 | Q9: Live, Asynchronous, Independent | R9: Low-Moderate; visual-first | S9: Operations | T9: Algebraic expressions and equations | U9: Mapped / not yet built | V9: Canonical unit; lesson sequence to be authored from mapped Stepping Stones. | W9: Curriculum map evidence only | X9: GreenPrint v1.1 / map v0.2
A10: NEO-MATH-DISC-06 | B10: Foundations | C10: Flexible entry | D10: 6 | E10: Spatial Reasoning | F10: Shape, Space and Measure Around Me | G10: How much geometry is hiding in an ordinary room? | H10: recognise angle and shape properties; measure accurately; calculate simple perimeter and area; use units; explain a spatial decision | I10: Movement | J10: Connection, Creativity | K10: Strong | L10: Room Geometry Explorer | M10: Square grid | N10: Annotated Space Audit | O10: NC KS3 Geometry; FS L1/L2 | P10: NC KS3 Geometry/Measures; FS L1 20-26; FS L2 14-22 | Q10: Live, Asynchronous, Independent | R10: Moderate; optional off-screen movement | S10: Number confidence | T10: Scale, constructions and modelling | U10: Mapped / not yet built | V10: Canonical unit; lesson sequence to be authored from mapped Stepping Stones. | W10: Curriculum map evidence only | X10: GreenPrint v1.1 / map v0.2
A11: NEO-MATH-DISC-07 | B11: Foundations | C11: Flexible entry | D11: 7 | E11: Data & Uncertainty | F11: What Can Data Really Tell Me? | G11: When should I trust a chart, average or probability claim? | H11: read tables and charts; choose an average; recognise range; use probability language; ask what data cannot show | I11: Reflection | J11: Connection, Creativity | K11: Strong | L11: Claim–Evidence Data Detective | M11: Blank | N11: One-Page Data Claim Review | O11: NC KS3 Statistics/Probability; FS L1/L2 | P11: NC KS3 Statistics/Probability; FS L1 27-31; FS L2 23-28 | Q11: Live, Asynchronous, Independent | R11: Moderate; one claim at a time | S11: Number confidence | T11: Statistical enquiry and probability models | U11: Mapped / not yet built | V11: Canonical unit; lesson sequence to be authored from mapped Stepping Stones. | W11: Curriculum map evidence only | X11: GreenPrint v1.1 / map v0.2
A12: NEO-MATH-DISC-08 | B12: Foundations | C12: Flexible entry | D12: 8 | E12: Financial & Applied Reasoning | F12: Maths for a Real Decision | G12: Can I use maths to make one decision that matters to me? | H12: identify needed information; choose operations; estimate; calculate; interpret an answer; explain a decision and limitation | I12: Connection | J12: Creativity, Reflection, Nutrition | K12: Strong | L12: Decision Model Builder | M12: Blank | N12: Personal Applied Maths Decision Card | O12: FS L1/L2; NEO canonical | P12: FS problem solving and decision making; pathway bridge | Q12: Live, Asynchronous, Independent | R12: Variable; learner chooses context | S12: Any Discovery unit | T12: Year-group or Functional pathway | U12: Mapped / not yet built | V12: Canonical unit; lesson sequence to be authored from mapped Stepping Stones. | W12: Curriculum map evidence only | X12: GreenPrint v1.1 / map v0.2
A13: NEO-MATH-Y7-01 | B13: Foundations | C13: Year 7 | D13: 1 | E13: Number Sense | F13: How Much Is a Digit Worth? | G13: Can the same digit represent completely different amounts? | H13: use place value with integers and decimals; explain tenfold relationships; use placeholder zero; partition numbers; move between representations | I13: Connection | J13: Rest, Reflection | K13: Strong | L13: Place-Value Magnifier + Digit Detective | M13: Square grid | N13: Place-Value Exhibition | O13: NC KS3 | P13: KS3 Number / Working Mathematically | Q13: Live, Asynchronous, Independent | R13: Low-Moderate; isolate one digit | S13: Discovery number confidence or KS2 place value | T13: Estimation, integers and operations | U13: Mapped / not yet built | V13: Reference prototype architecture | W13: Curriculum map evidence only | X13: GreenPrint v1.1 / map v0.2
A14: NEO-MATH-Y7-02 | B14: Foundations | C14: Year 7 | D14: 2 | E14: Number Sense | F14: Calculations That Make Sense | G14: How can an estimate protect me from a convincing wrong answer? | H14: use four operations; follow operation order; estimate; use inverse operations; calculate with directed numbers; check reasonableness | I14: Reflection | J14: Rest, Creativity | K14: Strong | L14: Estimate–Calculate–Check Lab | M14: Blank | N14: Error-Proof Calculation Guide | O14: NC KS3; FS L1/L2 | P14: KS3 Number; FS L1 2-7,15; FS L2 1-2,12 | Q14: Live, Asynchronous, Independent | R14: Moderate | S14: Place value | T14: Factors, multiples and algebra | U14: Mapped / not yet built | V14: Canonical unit; lesson sequence to be authored from mapped Stepping Stones. | W14: Curriculum map evidence only | X14: GreenPrint v1.1 / map v0.2
A15: NEO-MATH-Y7-03 | B15: Foundations | C15: Year 7 | D15: 3 | E15: Structure & Generalisation | F15: Patterns, Factors and Hidden Structure | G15: What do numbers reveal when we organise them differently? | H15: identify factors and multiples; recognise primes; find HCF/LCM; use powers; generalise patterns; test conjectures | I15: Creativity | J15: Connection, Reflection | K15: Strong | L15: Factor Web + Pattern Lock Builder | M15: Square grid | N15: Number Structure Museum Card | O15: NC KS3 | P15: KS3 Number and Algebra | Q15: Live, Asynchronous, Independent | R15: Moderate | S15: Operations | T15: Algebraic expressions and sequences | U15: Mapped / not yet built | V15: Canonical unit; lesson sequence to be authored from mapped Stepping Stones. | W15: Curriculum map evidence only | X15: GreenPrint v1.1 / map v0.2
A16: NEO-MATH-Y7-04 | B16: Foundations | C16: Year 7 | D16: 4 | E16: Proportional Reasoning | F16: One Amount, Three Languages | G16: How can fractions, decimals and percentages describe the same share? | H16: simplify fractions; find equivalent fractions; convert FDP; compare FDP; calculate fractions and percentages of amounts; explain representation choice | I16: Connection | J16: Creativity, Reflection | K16: Strong | L16: FDP Converter with Bar/Line Toggle | M16: Double number line | N16: FDP Translation Guide | O16: NC KS3; FS L1/L2 | P16: KS3 Number/Ratio; FS L1 8-17; FS L2 4-10 | Q16: Live, Asynchronous, Independent | R16: Moderate | S16: Number operations | T16: Ratio and proportion | U16: Mapped / not yet built | V16: Canonical unit; lesson sequence to be authored from mapped Stepping Stones. | W16: Curriculum map evidence only | X16: GreenPrint v1.1 / map v0.2
... A72: NEO-MATH-FS-10 | B72: Foundations | C72: FS L1/L2 flexible | D72: 10 | E72: Self-Regulated Mathematical Learning | F72: Functional Skills Assessment Navigation | G72: How can I stay oriented when a problem has several steps and lots of words? | H72: read mathematical information; identify operations; plan steps; use required accuracy; check sense; explain results; use calculator/non-calculator strategies | I72: Rest | J72: Reflection, Connection | K72: Strong | L72: Problem Step Mapper | M72: Blank | N72: Personal Problem-Solving Navigation Card | O72: Pearson Functional Skills Maths L1/L2 | P72: FS L1/L2 problem solving criteria; Section A non-calculator and Section B calculator structure | Q72: Live, Asynchronous, Independent | R72: Moderate; chunked text and step reveal | S72: Applied decision project | T72: On-demand assessment / next pathway | U72: Mapped / not yet built | V72: Canonical unit; lesson sequence to be authored from mapped Stepping Stones. | W72: Curriculum map evidence only | X72: GreenPrint v1.1 / map v0.2

Sheet Stepping Stones
A1: NEO Mathematics Canonical Stepping Stones — Pathways
A2: Portable learner-facing outcomes with pathway and internal stage recorded separately.
A4: Stepping Stone ID | B4: Unit ID | C4: Pathway | D4: Internal Stage | E4: Strand | F4: Unit Title | G4: Canonical Learning Statement | H4: Primary Cornerstone | I4: Secondary Cornerstones | J4: Mode(s) | K4: Suggested Evidence Types | L4: Prerequisite Connection | M4: Next Connection | N4: Current Status | O4: Evidence Link
A5: NEO-MATH-DISC-01-SRL-01 | B5: NEO-MATH-DISC-01 | C5: Foundations | D5: Flexible entry | E5: Self-Regulated Mathematical Learning | F5: Finding My Maths Starting Point | G5: Notice mathematical strengths | H5: Connection | I5: Reflection, Rest | J5: Live, Asynchronous, Independent | K5: Explanation; interactive choices; Scratchpad working; portfolio evidence | L5: None | M5: Place value; calculation; FDP; applied routes | N5: Mapped | O5: Attach live evidence through Foundations Coverage Map
A6: NEO-MATH-DISC-01-SRL-02 | B6: NEO-MATH-DISC-01 | C6: Foundations | D6: Flexible entry | E6: Self-Regulated Mathematical Learning | F6: Finding My Maths Starting Point | G6: Try different representations | H6: Connection | I6: Reflection, Rest | J6: Live, Asynchronous, Independent | K6: Explanation; interactive choices; Scratchpad working; portfolio evidence | L6: None | M6: Place value; calculation; FDP; applied routes | N6: Mapped | O6: Attach live evidence through Foundations Coverage Map
A7: NEO-MATH-DISC-01-SRL-03 | B7: NEO-MATH-DISC-01 | C7: Foundations | D7: Flexible entry | E7: Self-Regulated Mathematical Learning | F7: Finding My Maths Starting Point | G7: Use support tools | H7: Connection | I7: Reflection, Rest | J7: Live, Asynchronous, Independent | K7: Explanation; interactive choices; Scratchpad working; portfolio evidence | L7: None | M7: Place value; calculation; FDP; applied routes | N7: Mapped | O7: Attach live evidence through Foundations Coverage Map
A8: NEO-MATH-DISC-01-SRL-04 | B8: NEO-MATH-DISC-01 | C8: Foundations | D8: Flexible entry | E8: Self-Regulated Mathematical Learning | F8: Finding My Maths Starting Point | G8: Explain what helps | H8: Connection | I8: Reflection, Rest | J8: Live, Asynchronous, Independent | K8: Explanation; interactive choices; Scratchpad working; portfolio evidence | L8: None | M8: Place value; calculation; FDP; applied routes | N8: Mapped | O8: Attach live evidence through Foundations Coverage Map
A9: NEO-MATH-DISC-01-SRL-05 | B9: NEO-MATH-DISC-01 | C9: Foundations | D9: Flexible entry | E9: Self-Regulated Mathematical Learning | F9: Finding My Maths Starting Point | G9: Choose a next Stepping Stone | H9: Connection | I9: Reflection, Rest | J9: Live, Asynchronous, Independent | K9: Explanation; interactive choices; Scratchpad working; portfolio evidence | L9: None | M9: Place value; calculation; FDP; applied routes | N9: Mapped | O9: Attach live evidence through Foundations Coverage Map
A10: NEO-MATH-DISC-02-NUM-01 | B10: NEO-MATH-DISC-02 | C10: Foundations | D10: Flexible entry | E10: Number Sense | F10: Numbers I Can Trust | G10: Read and compare integers and decimals | H10: Rest | I10: Connection, Reflection | J10: Live, Asynchronous, Independent | K10: Explanation; interactive choices; Scratchpad working; portfolio evidence | L10: Maths Route Finder | M10: Operations and equivalence | N10: Mapped | O10: Attach live evidence through Foundations Coverage Map
A11: NEO-MATH-DISC-02-NUM-02 | B11: NEO-MATH-DISC-02 | C11: Foundations | D11: Flexible entry | E11: Number Sense | F11: Numbers I Can Trust | G11: Use place value | H11: Rest | I11: Connection, Reflection | J11: Live, Asynchronous, Independent | K11: Explanation; interactive choices; Scratchpad working; portfolio evidence | L11: Maths Route Finder | M11: Operations and equivalence | N11: Mapped | O11: Attach live evidence through Foundations Coverage Map
A12: NEO-MATH-DISC-02-NUM-03 | B12: NEO-MATH-DISC-02 | C12: Foundations | D12: Flexible entry | E12: Number Sense | F12: Numbers I Can Trust | G12: Locate zero | H12: Rest | I12: Connection, Reflection | J12: Live, Asynchronous, Independent | K12: Explanation; interactive choices; Scratchpad working; portfolio evidence | L12: Maths Route Finder | M12: Operations and equivalence | N12: Mapped | O12: Attach live evidence through Foundations Coverage Map
A13: NEO-MATH-DISC-02-NUM-04 | B13: NEO-MATH-DISC-02 | C13: Foundations | D13: Flexible entry | E13: Number Sense | F13: Numbers I Can Trust | G13: Estimate | H13: Rest | I13: Connection, Reflection | J13: Live, Asynchronous, Independent | K13: Explanation; interactive choices; Scratchpad working; portfolio evidence | L13: Maths Route Finder | M13: Operations and equivalence | N13: Mapped | O13: Attach live evidence through Foundations Coverage Map
A14: NEO-MATH-DISC-02-NUM-05 | B14: NEO-MATH-DISC-02 | C14: Foundations | D14: Flexible entry | E14: Number Sense | F14: Numbers I Can Trust | G14: Check reasonableness | H14: Rest | I14: Connection, Reflection | J14: Live, Asynchronous, Independent | K14: Explanation; interactive choices; Scratchpad working; portfolio evidence | L14: Maths Route Finder | M14: Operations and equivalence | N14: Mapped | O14: Attach live evidence through Foundations Coverage Map
A15: NEO-MATH-DISC-03-NUM-01 | B15: NEO-MATH-DISC-03 | C15: Foundations | D15: Flexible entry | E15: Number Sense | F15: Operations as Choices | G15: Select a calculation strategy | H15: Creativity | I15: Reflection, Rest | J15: Live, Asynchronous, Independent | K15: Explanation; interactive choices; Scratchpad working; portfolio evidence | L15: Place value | M15: Fractions, percentages and algebra | N15: Mapped | O15: Attach live evidence through Foundations Coverage Map
... A399: NEO-MATH-FS-10-SRL-07 | B399: NEO-MATH-FS-10 | C399: Foundations | D399: FS L1/L2 flexible | E399: Self-Regulated Mathematical Learning | F399: Functional Skills Assessment Navigation | G399: Use calculator/non-calculator strategies | H399: Rest | I399: Reflection, Connection | J399: Live, Asynchronous, Independent | K399: Explanation; interactive choices; Scratchpad working; portfolio evidence | L399: Applied decision project | M399: On-demand assessment / next pathway | N399: Mapped | O399: Attach live evidence through Foundations Coverage Map

Sheet Qualification Overlays
A1: Qualification Overlay Map
A2: Overlay references describe where external frameworks assess canonical NEO mathematics. They do not define the curriculum spine. Verify specification details at annual review.
A4: Overlay Map ID | B4: Unit ID | C4: Pathway | D4: Unit Title | E4: Overlay | F4: Tier / Level | G4: Specification Reference | H4: Canonical Link Summary | I4: Source URL | J4: Review Note
A5: OV-0001 | B5: NEO-MATH-DISC-01 | C5: Discovery / Reconnection | D5: Finding My Maths Starting Point | E5: NEO Canonical / Discovery | F5: Pathway diagnostic | G5: Not an awarding-body unit; informs pathway entry | H5: Outcome supports re-engagement, entry-point identification and movement into the canonical spine. | J5: No external assessment claim; evidence informs pathway planning.
A6: OV-0002 | B6: NEO-MATH-DISC-02 | C6: Discovery / Reconnection | D6: Numbers I Can Trust | E6: National Curriculum KS3 Mathematics | F6: KS3 | G6: NC KS3 Number; FS L1 1-3,10-12; FS L2 1-2,9-10 | H6: Canonical Stepping Stones build fluency, reasoning, representation and problem solving within the named domain. | I6: https://www.gov.uk/government/publications/national-curriculum-in-england-mathematics-programmes-of-study/national-curriculum-in-england-mathematics-programmes-of-study | J6: Statutory KS3 programme; sequence by readiness and secure understanding.
A7: OV-0003 | B7: NEO-MATH-DISC-02 | C7: Discovery / Reconnection | D7: Numbers I Can Trust | E7: Pearson Edexcel Functional Skills Mathematics (2019) | F7: Level 1 / Level 2 differentiated | G7: NC KS3 Number; FS L1 1-3,10-12; FS L2 1-2,9-10 | H7: Canonical learning is applied to realistic problems, decision making, checking reasonableness and communicating results. | I7: https://qualifications.pearson.com/en/qualifications/edexcel-functional-skills/maths-2019.html | J7: Pearson page lists L1/L2 review date 31 August 2028; verify at annual review.
A8: OV-0004 | B8: NEO-MATH-DISC-03 | C8: Discovery / Reconnection | D8: Operations as Choices | E8: National Curriculum KS3 Mathematics | F8: KS3 | G8: NC KS3 fluency/problem solving; FS L1 4,7,15; FS L2 2,12 | H8: Canonical Stepping Stones build fluency, reasoning, representation and problem solving within the named domain. | I8: https://www.gov.uk/government/publications/national-curriculum-in-england-mathematics-programmes-of-study/national-curriculum-in-england-mathematics-programmes-of-study | J8: Statutory KS3 programme; sequence by readiness and secure understanding.
A9: OV-0005 | B9: NEO-MATH-DISC-03 | C9: Discovery / Reconnection | D9: Operations as Choices | E9: Pearson Edexcel Functional Skills Mathematics (2019) | F9: Level 1 / Level 2 differentiated | G9: NC KS3 fluency/problem solving; FS L1 4,7,15; FS L2 2,12 | H9: Canonical learning is applied to realistic problems, decision making, checking reasonableness and communicating results. | I9: https://qualifications.pearson.com/en/qualifications/edexcel-functional-skills/maths-2019.html | J9: Pearson page lists L1/L2 review date 31 August 2028; verify at annual review.
A10: OV-0006 | B10: NEO-MATH-DISC-04 | C10: Discovery / Reconnection | D10: Fractions, Decimals and Percentages as One Family | E10: National Curriculum KS3 Mathematics | F10: KS3 | G10: NC KS3 Number and Ratio; FS L1 8-17; FS L2 4-10 | H10: Canonical Stepping Stones build fluency, reasoning, representation and problem solving within the named domain. | I10: https://www.gov.uk/government/publications/national-curriculum-in-england-mathematics-programmes-of-study/national-curriculum-in-england-mathematics-programmes-of-study | J10: Statutory KS3 programme; sequence by readiness and secure understanding.
A11: OV-0007 | B11: NEO-MATH-DISC-04 | C11: Discovery / Reconnection | D11: Fractions, Decimals and Percentages as One Family | E11: Pearson Edexcel Functional Skills Mathematics (2019) | F11: Level 1 / Level 2 differentiated | G11: NC KS3 Number and Ratio; FS L1 8-17; FS L2 4-10 | H11: Canonical learning is applied to realistic problems, decision making, checking reasonableness and communicating results. | I11: https://qualifications.pearson.com/en/qualifications/edexcel-functional-skills/maths-2019.html | J11: Pearson page lists L1/L2 review date 31 August 2028; verify at annual review.
A12: OV-0008 | B12: NEO-MATH-DISC-05 | C12: Discovery / Reconnection | D12: Patterns Before Letters | E12: National Curriculum KS3 Mathematics | F12: KS3 | G12: NC KS3 Algebra; FS L1 5; FS L2 3 | H12: Canonical Stepping Stones build fluency, reasoning, representation and problem solving within the named domain. | I12: https://www.gov.uk/government/publications/national-curriculum-in-england-mathematics-programmes-of-study/national-curriculum-in-england-mathematics-programmes-of-study | J12: Statutory KS3 programme; sequence by readiness and secure understanding.
A13: OV-0009 | B13: NEO-MATH-DISC-05 | C13: Discovery / Reconnection | D13: Patterns Before Letters | E13: Pearson Edexcel Functional Skills Mathematics (2019) | F13: Level 1 / Level 2 differentiated | G13: NC KS3 Algebra; FS L1 5; FS L2 3 | H13: Canonical learning is applied to realistic problems, decision making, checking reasonableness and communicating results. | I13: https://qualifications.pearson.com/en/qualifications/edexcel-functional-skills/maths-2019.html | J13: Pearson page lists L1/L2 review date 31 August 2028; verify at annual review.
A14: OV-0010 | B14: NEO-MATH-DISC-06 | C14: Discovery / Reconnection | D14: Shape, Space and Measure Around Me | E14: National Curriculum KS3 Mathematics | F14: KS3 | G14: NC KS3 Geometry/Measures; FS L1 20-26; FS L2 14-22 | H14: Canonical Stepping Stones build fluency, reasoning, representation and problem solving within the named domain. | I14: https://www.gov.uk/government/publications/national-curriculum-in-england-mathematics-programmes-of-study/national-curriculum-in-england-mathematics-programmes-of-study | J14: Statutory KS3 programme; sequence by readiness and secure understanding.
A15: OV-0011 | B15: NEO-MATH-DISC-06 | C15: Discovery / Reconnection | D15: Shape, Space and Measure Around Me | E15: Pearson Edexcel Functional Skills Mathematics (2019) | F15: Level 1 / Level 2 differentiated | G15: NC KS3 Geometry/Measures; FS L1 20-26; FS L2 14-22 | H15: Canonical learning is applied to realistic problems, decision making, checking reasonableness and communicating results. | I15: https://qualifications.pearson.com/en/qualifications/edexcel-functional-skills/maths-2019.html | J15: Pearson page lists L1/L2 review date 31 August 2028; verify at annual review.
A16: OV-0012 | B16: NEO-MATH-DISC-07 | C16: Discovery / Reconnection | D16: What Can Data Really Tell Me? | E16: National Curriculum KS3 Mathematics | F16: KS3 | G16: NC KS3 Statistics/Probability; FS L1 27-31; FS L2 23-28 | H16: Canonical Stepping Stones build fluency, reasoning, representation and problem solving within the named domain. | I16: https://www.gov.uk/government/publications/national-curriculum-in-england-mathematics-programmes-of-study/national-curriculum-in-england-mathematics-programmes-of-study | J16: Statutory KS3 programme; sequence by readiness and secure understanding.
A17: OV-0013 | B17: NEO-MATH-DISC-07 | C17: Discovery / Reconnection | D17: What Can Data Really Tell Me? | E17: Pearson Edexcel Functional Skills Mathematics (2019) | F17: Level 1 / Level 2 differentiated | G17: NC KS3 Statistics/Probability; FS L1 27-31; FS L2 23-28 | H17: Canonical learning is applied to realistic problems, decision making, checking reasonableness and communicating results. | I17: https://qualifications.pearson.com/en/qualifications/edexcel-functional-skills/maths-2019.html | J17: Pearson page lists L1/L2 review date 31 August 2028; verify at annual review.
... A114: OV-0110 | B114: NEO-MATH-FS-10 | C114: Functional & Applied Mathematics | D114: Functional Skills Assessment Navigation | E114: Pearson Edexcel Functional Skills Mathematics (2019) | F114: Level 1 / Level 2 differentiated | G114: FS L1/L2 problem solving criteria; Section A non-calculator and Section B calculator structure | H114: Canonical learning is applied to realistic problems, decision making, checking reasonableness and communicating results. | I114: https://qualifications.pearson.com/en/qualifications/edexcel-functional-skills/maths-2019.html | J114: Pearson page lists L1/L2 review date 31 August 2028; verify at annual review.

Sheet Cornerstone Map
A1: NEO Cornerstone Distribution and Unit Fit
A2: Cornerstones are design lenses. Fit is intentionally uneven: Nutrition is contextual in many abstract mathematics units and should not be forced.
A4: Cornerstone | B4: Primary Units | C4: % of 68 Units | D4: Design Reminder
A5: Connection | B5: =COUNTIF($G$15:$G$82,A5) -> 22 | C5: =B5/68 -> 0.32352941 | D5: Make mathematical relationships and human dialogue visible.
A6: Movement | B6: =COUNTIF($G$15:$G$82,A6) -> 14 | C6: =B6/68 -> 0.20588235 | D6: Treat mathematical ideas as dynamic; trace change or movement.
A7: Creativity | B7: =COUNTIF($G$15:$G$82,A7) -> 10 | C7: =B7/68 -> 0.14705882 | D7: Invite conjecture, multiple routes, making and model-building.
A8: Reflection | B8: =COUNTIF($G$15:$G$82,A8) -> 19 | C8: =B8/68 -> 0.27941176 | D8: Surface reasoning, misconceptions, proof and metacognition.
A9: Rest | B9: =COUNTIF($G$15:$G$82,A9) -> 3 | C9: =B9/68 -> 0.044117647 | D9: Chunk, regulate sensory load and protect the right to pause.
A10: Nutrition | B10: =COUNTIF($G$15:$G$82,A10) -> 0 | C10: =B10/68 -> 0 | D10: Use food/body/health/sustainability contexts only where genuine.
A14: Unit ID | B14: Pathway | C14: Internal Stage | D14: Strand | E14: Unit Title | F14: Driving Question | G14: Primary Cornerstone | H14: Secondary Cornerstone(s) | I14: Fit | J14: What the Cornerstone Does Mathematically | K14: Scratchpad / Inquiry Link | L14: Sensory / Pacing Note
A15: NEO-MATH-DISC-01 | B15: Discovery / Reconnection | C15: Flexible entry | D15: Self-Regulated Mathematical Learning | E15: Finding My Maths Starting Point | F15: What happens when maths begins with what I already notice? | G15: Connection | H15: Reflection, Rest | I15: Strong | J15: Makes relationships, equivalence, dependency or communication explicit. | K15: Maths Route Finder: visual, numerical and contextual mini-challenges | Blank / Square grid | L15: Low; choice-rich, no timed score
A16: NEO-MATH-DISC-02 | B16: Discovery / Reconnection | C16: Flexible entry | D16: Number Sense | E16: Numbers I Can Trust | F16: How can I make a number less crowded? | G16: Rest | H16: Connection, Reflection | I16: Strong | J16: Uses chunking, consolidation, low-stakes retrieval or the mathematics of zero/space. | K16: Place-Value Magnifier and Number Line Zoom | Square grid | L16: Low-Moderate; one digit/interval at a time
A17: NEO-MATH-DISC-03 | B17: Discovery / Reconnection | C17: Flexible entry | D17: Number Sense | E17: Operations as Choices | F17: Is there more than one sensible way to calculate? | G17: Creativity | H17: Reflection, Rest | I17: Strong | J17: Invites conjecture, model-building, design or more than one valid route. | K17: Strategy Switcher: compare mental, written and calculator routes | Blank | L17: Moderate; method menu reduces overload
A18: NEO-MATH-DISC-04 | B18: Discovery / Reconnection | C18: Flexible entry | D18: Proportional Reasoning | E18: Fractions, Decimals and Percentages as One Family | F18: Can three different-looking numbers mean the same amount? | G18: Connection | H18: Creativity, Reflection | I18: Strong | J18: Makes relationships, equivalence, dependency or communication explicit. | K18: FDP Representation Carousel | Double number line | L18: Moderate; representation choice
A19: NEO-MATH-DISC-05 | B19: Discovery / Reconnection | C19: Flexible entry | D19: Structure & Generalisation | E19: Patterns Before Letters | F19: Can a pattern explain itself before we use algebra? | G19: Creativity | H19: Connection, Reflection | I19: Strong | J19: Invites conjecture, model-building, design or more than one valid route. | K19: Pattern Machine and Rule Builder | Square grid | L19: Low-Moderate; visual-first
A20: NEO-MATH-DISC-06 | B20: Discovery / Reconnection | C20: Flexible entry | D20: Spatial Reasoning | E20: Shape, Space and Measure Around Me | F20: How much geometry is hiding in an ordinary room? | G20: Movement | H20: Connection, Creativity | I20: Strong | J20: Makes change, transformation, rate or spatial movement visible. | K20: Room Geometry Explorer | Square grid | L20: Moderate; optional off-screen movement
A21: NEO-MATH-DISC-07 | B21: Discovery / Reconnection | C21: Flexible entry | D21: Data & Uncertainty | E21: What Can Data Really Tell Me? | F21: When should I trust a chart, average or probability claim? | G21: Reflection | H21: Connection, Creativity | I21: Strong | J21: Builds explanation, proof, error repair or strategy review into the mathematics. | K21: Claim–Evidence Data Detective | Blank | L21: Moderate; one claim at a time
A22: NEO-MATH-DISC-08 | B22: Discovery / Reconnection | C22: Flexible entry | D22: Financial & Applied Reasoning | E22: Maths for a Real Decision | F22: Can I use maths to make one decision that matters to me? | G22: Connection | H22: Creativity, Reflection, Nutrition | I22: Strong | J22: Makes relationships, equivalence, dependency or communication explicit. | K22: Decision Model Builder | Blank | L22: Variable; learner chooses context
A23: NEO-MATH-Y7-01 | B23: Year 7 Foundations | C23: Year 7 | D23: Number Sense | E23: How Much Is a Digit Worth? | F23: Can the same digit represent completely different amounts? | G23: Connection | H23: Rest, Reflection | I23: Strong | J23: Makes relationships, equivalence, dependency or communication explicit. | K23: Place-Value Magnifier + Digit Detective | Square grid | L23: Low-Moderate; isolate one digit
A24: NEO-MATH-Y7-02 | B24: Year 7 Foundations | C24: Year 7 | D24: Number Sense | E24: Calculations That Make Sense | F24: How can an estimate protect me from a convincing wrong answer? | G24: Reflection | H24: Rest, Creativity | I24: Strong | J24: Builds explanation, proof, error repair or strategy review into the mathematics. | K24: Estimate–Calculate–Check Lab | Blank | L24: Moderate
A25: NEO-MATH-Y7-03 | B25: Year 7 Foundations | C25: Year 7 | D25: Structure & Generalisation | E25: Patterns, Factors and Hidden Structure | F25: What do numbers reveal when we organise them differently? | G25: Creativity | H25: Connection, Reflection | I25: Strong | J25: Invites conjecture, model-building, design or more than one valid route. | K25: Factor Web + Pattern Lock Builder | Square grid | L25: Moderate
... A82: NEO-MATH-FS-10 | B82: Functional & Applied Mathematics | C82: FS L1/L2 flexible | D82: Self-Regulated Mathematical Learning | E82: Functional Skills Assessment Navigation | F82: How can I stay oriented when a problem has several steps and lots of words? | G82: Rest | H82: Reflection, Connection | I82: Strong | J82: Uses chunking, consolidation, low-stakes retrieval or the mathematics of zero/space. | K82: Problem Step Mapper | Blank | L82: Moderate; chunked text and step reveal

Sheet Interactive Tools
A1: Interactive Inquiry Tool Build Register
A2: Every tool should support inquiry rather than merely display content. Preferred rhythm: Predict → Sketch → Test → Notice → Revise.
A4: Tool ID | B4: Unit ID | C4: Pathway | D4: Unit Title | E4: Interactive Inquiry Tool | F4: Inquiry Move | G4: Core Learner Actions | H4: Scratchpad Preset | I4: Suggested Contextual Button | J4: Reusable Tool Family | K4: Tool Status | L4: Build Note
A5: TOOL-001 | B5: NEO-MATH-DISC-01 | C5: Discovery / Reconnection | D5: Finding My Maths Starting Point | E5: Maths Route Finder: visual, numerical and contextual mini-challenges | F5: Predict → Sketch → Test → Notice → Revise | G5: Change values; make a prediction; test; compare representations; explain what changed and what stayed the same. | H5: Blank / Square grid | I5: ✏️ Open Maths Scratchpad | J5: Navigation Tool | K5: Designed | L5: Keep all core interaction in-page; no external URL required.
A6: TOOL-002 | B6: NEO-MATH-DISC-02 | C6: Discovery / Reconnection | D6: Numbers I Can Trust | E6: Place-Value Magnifier and Number Line Zoom | F6: Predict → Sketch → Test → Notice → Revise | G6: Change values; make a prediction; test; compare representations; explain what changed and what stayed the same. | H6: Square grid | I6: ✏️ Open Maths Scratchpad | J6: Number Explorer | K6: Planned | L6: Keep all core interaction in-page; no external URL required.
A7: TOOL-003 | B7: NEO-MATH-DISC-03 | C7: Discovery / Reconnection | D7: Operations as Choices | E7: Strategy Switcher: compare mental, written and calculator routes | F7: Predict → Sketch → Test → Notice → Revise | G7: Change values; make a prediction; test; compare representations; explain what changed and what stayed the same. | H7: Blank | I7: ✏️ Open Maths Scratchpad | J7: Number Explorer | K7: Planned | L7: Keep all core interaction in-page; no external URL required.
A8: TOOL-004 | B8: NEO-MATH-DISC-04 | C8: Discovery / Reconnection | D8: Fractions, Decimals and Percentages as One Family | E8: FDP Representation Carousel | F8: Predict → Sketch → Test → Notice → Revise | G8: Change values; make a prediction; test; compare representations; explain what changed and what stayed the same. | H8: Double number line | I8: ✏️ Show the multiplier / relationship | J8: Scaling Lab | K8: Planned | L8: Keep all core interaction in-page; no external URL required.
A9: TOOL-005 | B9: NEO-MATH-DISC-05 | C9: Discovery / Reconnection | D9: Patterns Before Letters | E9: Pattern Machine and Rule Builder | F9: Predict → Sketch → Test → Notice → Revise | G9: Vary one element; notice invariance; conjecture a rule; test examples and repair a misconception. | H9: Square grid | I9: ✏️ Open Maths Scratchpad | J9: Structure Lab | K9: Planned | L9: Keep all core interaction in-page; no external URL required.
A10: TOOL-006 | B10: NEO-MATH-DISC-06 | C10: Discovery / Reconnection | D10: Shape, Space and Measure Around Me | E10: Room Geometry Explorer | F10: Predict → Sketch → Test → Notice → Revise | G10: Manipulate a diagram or constraint; sketch first; test a construction or measure; annotate the relationship. | H10: Square grid | I10: ✏️ Open Maths Scratchpad | J10: Geometry Studio | K10: Planned | L10: Keep all core interaction in-page; no external URL required.
A11: TOOL-007 | B11: NEO-MATH-DISC-07 | C11: Discovery / Reconnection | D11: What Can Data Really Tell Me? | E11: Claim–Evidence Data Detective | F11: Predict → Sketch → Test → Notice → Revise | G11: Inspect a claim or data display; change a condition; compare evidence; record a conclusion and caveat. | H11: Blank | I11: ✏️ Open Maths Scratchpad | J11: Evidence Lab | K11: Planned | L11: Keep all core interaction in-page; no external URL required.
A12: TOOL-008 | B12: NEO-MATH-DISC-08 | C12: Discovery / Reconnection | D12: Maths for a Real Decision | E12: Decision Model Builder | F12: Predict → Sketch → Test → Notice → Revise | G12: Enter realistic values; compare options; calculate; test assumptions; explain a recommendation. | H12: Blank | I12: ✏️ Open Maths Scratchpad | J12: Decision Lab | K12: Planned | L12: Keep all core interaction in-page; no external URL required.
A13: TOOL-009 | B13: NEO-MATH-Y7-01 | C13: Year 7 Foundations | D13: How Much Is a Digit Worth? | E13: Place-Value Magnifier + Digit Detective | F13: Predict → Sketch → Test → Notice → Revise | G13: Change values; make a prediction; test; compare representations; explain what changed and what stayed the same. | H13: Square grid | I13: ✏️ Open Maths Scratchpad | J13: Number Explorer | K13: Planned | L13: Keep all core interaction in-page; no external URL required.
A14: TOOL-010 | B14: NEO-MATH-Y7-02 | C14: Year 7 Foundations | D14: Calculations That Make Sense | E14: Estimate–Calculate–Check Lab | F14: Predict → Sketch → Test → Notice → Revise | G14: Change values; make a prediction; test; compare representations; explain what changed and what stayed the same. | H14: Blank | I14: ✏️ Open Maths Scratchpad | J14: Number Explorer | K14: Planned | L14: Keep all core interaction in-page; no external URL required.
A15: TOOL-011 | B15: NEO-MATH-Y7-03 | C15: Year 7 Foundations | D15: Patterns, Factors and Hidden Structure | E15: Factor Web + Pattern Lock Builder | F15: Predict → Sketch → Test → Notice → Revise | G15: Vary one element; notice invariance; conjecture a rule; test examples and repair a misconception. | H15: Square grid | I15: ✏️ Open Maths Scratchpad | J15: Structure Lab | K15: Planned | L15: Keep all core interaction in-page; no external URL required.
... A72: TOOL-068 | B72: NEO-MATH-FS-10 | C72: Functional & Applied Mathematics | D72: Functional Skills Assessment Navigation | E72: Problem Step Mapper | F72: Predict → Sketch → Test → Notice → Revise | G72: Change values; make a prediction; test; compare representations; explain what changed and what stayed the same. | H72: Blank | I72: ✏️ Open Maths Scratchpad | J72: Navigation Tool | K72: Planned | L72: Keep all core interaction in-page; no external URL required.

Sheet Portfolio & Mastery
A1: Portfolio Evidence and Mastery Outcomes
A2: A single piece of learner-owned evidence may demonstrate several canonical Stepping Stones and qualification overlay outcomes. Mastery is judged per outcome demonstration.
A4: Unit ID | B4: Pathway | C4: Internal Stage | D4: Strand | E4: Unit Title | F4: Portfolio / Evidence Product | G4: Alternative Evidence Forms | H4: Emerging | I4: Developing | J4: Secure | K4: Mastering | L4: Submission Pattern | M4: Learner Reflection Prompt | N4: Evidence Ownership Note
A5: NEO-MATH-DISC-01 | B5: Discovery / Reconnection | C5: Flexible entry | D5: Self-Regulated Mathematical Learning | E5: Finding My Maths Starting Point | F5: My Maths Map: strengths, supports and next steps | G5: Interactive choices; Scratchpad image; annotated solution; verbal teach-back; corrected misconception; short written or audio explanation | H5: Notices or attempts key ideas from notice mathematical strengths with support and can show one relevant representation. | I5: Uses familiar methods to try different representations and completes connected examples with prompts or checking support. | J5: Independently explain what helps and explains the mathematical relationship or reasoning in a familiar and one varied context. | K5: Selects efficient representations or strategies, applies the learning in an unfamiliar context, and can choose a next Stepping Stone with precise justification and reflection. | L5: NEO_Maths_Finding_My_Maths_Starting_Point_[FirstName]_[Date] | M5: What changed in my thinking? What support helped? What would I test or explain next? | N5: Learner owns the evidence; NEO owns canonical curriculum metadata.
A6: NEO-MATH-DISC-02 | B6: Discovery / Reconnection | C6: Flexible entry | D6: Number Sense | E6: Numbers I Can Trust | F6: Annotated Number Confidence Card | G6: Interactive choices; Scratchpad image; annotated solution; verbal teach-back; corrected misconception; short written or audio explanation | H6: Notices or attempts key ideas from read and compare integers and decimals with support and can show one relevant representation. | I6: Uses familiar methods to use place value and completes connected examples with prompts or checking support. | J6: Independently estimate and explains the mathematical relationship or reasoning in a familiar and one varied context. | K6: Selects efficient representations or strategies, applies the learning in an unfamiliar context, and can check reasonableness with precise justification and reflection. | L6: NEO_Maths_Numbers_I_Can_Trust_[FirstName]_[Date] | M6: What changed in my thinking? What support helped? What would I test or explain next? | N6: Learner owns the evidence; NEO owns canonical curriculum metadata.
A7: NEO-MATH-DISC-03 | B7: Discovery / Reconnection | C7: Flexible entry | D7: Number Sense | E7: Operations as Choices | F7: My Best Method Guide | G7: Interactive choices; Scratchpad image; annotated solution; verbal teach-back; corrected misconception; short written or audio explanation | H7: Notices or attempts key ideas from select a calculation strategy with support and can show one relevant representation. | I7: Uses familiar methods to use inverse operations and completes connected examples with prompts or checking support. | J7: Independently estimate first and explains the mathematical relationship or reasoning in a familiar and one varied context. | K7: Selects efficient representations or strategies, applies the learning in an unfamiliar context, and can explain a method choice with precise justification and reflection. | L7: NEO_Maths_Operations_as_Choices_[FirstName]_[Date] | M7: What changed in my thinking? What support helped? What would I test or explain next? | N7: Learner owns the evidence; NEO owns canonical curriculum metadata.
A8: NEO-MATH-DISC-04 | B8: Discovery / Reconnection | C8: Flexible entry | D8: Proportional Reasoning | E8: Fractions, Decimals and Percentages as One Family | F8: Equivalence Gallery | G8: Interactive choices; Scratchpad image; annotated solution; verbal teach-back; corrected misconception; short written or audio explanation | H8: Notices or attempts key ideas from recognise common equivalences with support and can show one relevant representation. | I8: Uses familiar methods to compare FDP and completes connected examples with prompts or checking support. | J8: Independently find fractions and percentages of quantities and explains the mathematical relationship or reasoning in a familiar and one varied context. | K8: Selects efficient representations or strategies, applies the learning in an unfamiliar context, and can choose a helpful representation with precise justification and reflection. | L8: NEO_Maths_Fractions_Decimals_and_Percentag_[FirstName]_[Date] | M8: What changed in my thinking? What support helped? What would I test or explain next? | N8: Learner owns the evidence; NEO owns canonical curriculum metadata.
A9: NEO-MATH-DISC-05 | B9: Discovery / Reconnection | C9: Flexible entry | D9: Structure & Generalisation | E9: Patterns Before Letters | F9: Pattern Rule Card with examples and non-examples | G9: Interactive choices; Scratchpad image; annotated solution; verbal teach-back; corrected misconception; short written or audio explanation | H9: Notices or attempts key ideas from continue sequences with support and can show one relevant representation. | I9: Uses familiar methods to describe a rule and completes connected examples with prompts or checking support. | J9: Independently substitute values and explains the mathematical relationship or reasoning in a familiar and one varied context. | K9: Selects efficient representations or strategies, applies the learning in an unfamiliar context, and can create and test a conjecture with precise justification and reflection. | L9: NEO_Maths_Patterns_Before_Letters_[FirstName]_[Date] | M9: What changed in my thinking? What support helped? What would I test or explain next? | N9: Learner owns the evidence; NEO owns canonical curriculum metadata.
A10: NEO-MATH-DISC-06 | B10: Discovery / Reconnection | C10: Flexible entry | D10: Spatial Reasoning | E10: Shape, Space and Measure Around Me | F10: Annotated Space Audit | G10: Interactive choices; Scratchpad image; annotated solution; verbal teach-back; corrected misconception; short written or audio explanation | H10: Notices or attempts key ideas from recognise angle and shape properties with support and can show one relevant representation. | I10: Uses familiar methods to measure accurately and completes connected examples with prompts or checking support. | J10: Independently use units and explains the mathematical relationship or reasoning in a familiar and one varied context. | K10: Selects efficient representations or strategies, applies the learning in an unfamiliar context, and can explain a spatial decision with precise justification and reflection. | L10: NEO_Maths_Shape_Space_and_Measure_Around_M_[FirstName]_[Date] | M10: What changed in my thinking? What support helped? What would I test or explain next? | N10: Learner owns the evidence; NEO owns canonical curriculum metadata.
A11: NEO-MATH-DISC-07 | B11: Discovery / Reconnection | C11: Flexible entry | D11: Data & Uncertainty | E11: What Can Data Really Tell Me? | F11: One-Page Data Claim Review | G11: Interactive choices; Scratchpad image; annotated solution; verbal teach-back; corrected misconception; short written or audio explanation | H11: Notices or attempts key ideas from read tables and charts with support and can show one relevant representation. | I11: Uses familiar methods to choose an average and completes connected examples with prompts or checking support. | J11: Independently use probability language and explains the mathematical relationship or reasoning in a familiar and one varied context. | K11: Selects efficient representations or strategies, applies the learning in an unfamiliar context, and can ask what data cannot show with precise justification and reflection. | L11: NEO_Maths_What_Can_Data_Really_Tell_Me_[FirstName]_[Date] | M11: What changed in my thinking? What support helped? What would I test or explain next? | N11: Learner owns the evidence; NEO owns canonical curriculum metadata.
A12: NEO-MATH-DISC-08 | B12: Discovery / Reconnection | C12: Flexible entry | D12: Financial & Applied Reasoning | E12: Maths for a Real Decision | F12: Personal Applied Maths Decision Card | G12: Interactive choices; Scratchpad image; annotated solution; verbal teach-back; corrected misconception; short written or audio explanation | H12: Notices or attempts key ideas from identify needed information with support and can show one relevant representation. | I12: Uses familiar methods to choose operations and completes connected examples with prompts or checking support. | J12: Independently calculate and explains the mathematical relationship or reasoning in a familiar and one varied context. | K12: Selects efficient representations or strategies, applies the learning in an unfamiliar context, and can explain a decision and limitation with precise justification and reflection. | L12: NEO_Maths_Maths_for_a_Real_Decision_[FirstName]_[Date] | M12: What changed in my thinking? What support helped? What would I test or explain next? | N12: Learner owns the evidence; NEO owns canonical curriculum metadata.
A13: NEO-MATH-Y7-01 | B13: Year 7 Foundations | C13: Year 7 | D13: Number Sense | E13: How Much Is a Digit Worth? | F13: Place-Value Exhibition | G13: Interactive choices; Scratchpad image; annotated solution; verbal teach-back; corrected misconception; short written or audio explanation | H13: Notices or attempts key ideas from use place value with integers and decimals with support and can show one relevant representation. | I13: Uses familiar methods to explain tenfold relationships and completes connected examples with prompts or checking support. | J13: Independently partition numbers and explains the mathematical relationship or reasoning in a familiar and one varied context. | K13: Selects efficient representations or strategies, applies the learning in an unfamiliar context, and can move between representations with precise justification and reflection. | L13: NEO_Maths_How_Much_Is_a_Digit_Worth_[FirstName]_[Date] | M13: What changed in my thinking? What support helped? What would I test or explain next? | N13: Learner owns the evidence; NEO owns canonical curriculum metadata.
A14: NEO-MATH-Y7-02 | B14: Year 7 Foundations | C14: Year 7 | D14: Number Sense | E14: Calculations That Make Sense | F14: Error-Proof Calculation Guide | G14: Interactive choices; Scratchpad image; annotated solution; verbal teach-back; corrected misconception; short written or audio explanation | H14: Notices or attempts key ideas from use four operations with support and can show one relevant representation. | I14: Uses familiar methods to follow operation order and completes connected examples with prompts or checking support. | J14: Independently use inverse operations and explains the mathematical relationship or reasoning in a familiar and one varied context. | K14: Selects efficient representations or strategies, applies the learning in an unfamiliar context, and can check reasonableness with precise justification and reflection. | L14: NEO_Maths_Calculations_That_Make_Sense_[FirstName]_[Date] | M14: What changed in my thinking? What support helped? What would I test or explain next? | N14: Learner owns the evidence; NEO owns canonical curriculum metadata.
A15: NEO-MATH-Y7-03 | B15: Year 7 Foundations | C15: Year 7 | D15: Structure & Generalisation | E15: Patterns, Factors and Hidden Structure | F15: Number Structure Museum Card | G15: Interactive choices; Scratchpad image; annotated solution; verbal teach-back; corrected misconception; short written or audio explanation | H15: Notices or attempts key ideas from identify factors and multiples with support and can show one relevant representation. | I15: Uses familiar methods to recognise primes and completes connected examples with prompts or checking support. | J15: Independently use powers and explains the mathematical relationship or reasoning in a familiar and one varied context. | K15: Selects efficient representations or strategies, applies the learning in an unfamiliar context, and can test conjectures with precise justification and reflection. | L15: NEO_Maths_Patterns_Factors_and_Hidden_Stru_[FirstName]_[Date] | M15: What changed in my thinking? What support helped? What would I test or explain next? | N15: Learner owns the evidence; NEO owns canonical curriculum metadata.
... A72: NEO-MATH-FS-10 | B72: Functional & Applied Mathematics | C72: FS L1/L2 flexible | D72: Self-Regulated Mathematical Learning | E72: Functional Skills Assessment Navigation | F72: Personal Problem-Solving Navigation Card | G72: Interactive choices; Scratchpad image; annotated solution; verbal teach-back; corrected misconception; short written or audio explanation | H72: Notices or attempts key ideas from read mathematical information with support and can show one relevant representation. | I72: Uses familiar methods to identify operations and completes connected examples with prompts or checking support. | J72: Independently use required accuracy and explains the mathematical relationship or reasoning in a familiar and one varied context. | K72: Selects efficient representations or strategies, applies the learning in an unfamiliar context, and can use calculator/non-calculator strategies with precise justification and reflection. | L72: NEO_Maths_Functional_Skills_Assessment_Nav_[FirstName]_[Date] | M72: What changed in my thinking? What support helped? What would I test or explain next? | N72: Learner owns the evidence; NEO owns canonical curriculum metadata.

Sheet Build Tracker
A1: NEO Mathematics Curriculum Build Tracker — Pathways
A2: Operational register from mapped curriculum to lesson package, review, evidence and lock.
A4: Unit ID | B4: Pathway | C4: Internal Stage | D4: Unit Title | E4: Curriculum Map | F4: Interactive Tool | G4: HTML Lesson | H4: Practice Companion | I4: Learner Guide | J4: Adult Guidance | K4: Review | L4: Current Status | M4: Priority / Note | N4: Evidence / Live Count | O4: GreenPrint Version
A5: NEO-MATH-DISC-01 | B5: Foundations | C5: Flexible entry | D5: Finding My Maths Starting Point | E5: Complete | F5: Designed | G5: Planned | H5: Planned | I5: Planned | J5: Planned | K5: Not started | L5: Planned | M5: Sequence after spine review | N5: No live artifact linked | O5: GreenPrint v1.1 / map v0.2
A6: NEO-MATH-DISC-02 | B6: Foundations | C6: Flexible entry | D6: Numbers I Can Trust | E6: Complete | F6: Planned | G6: Planned | H6: Planned | I6: Planned | J6: Planned | K6: Not started | L6: Planned | M6: Sequence after spine review | N6: 1 lesson + 2 guides | O6: GreenPrint v1.1 / map v0.2
A7: NEO-MATH-DISC-03 | B7: Foundations | C7: Flexible entry | D7: Operations as Choices | E7: Complete | F7: Planned | G7: Planned | H7: Planned | I7: Planned | J7: Planned | K7: Not started | L7: Planned | M7: Sequence after spine review | N7: No live artifact linked | O7: GreenPrint v1.1 / map v0.2
A8: NEO-MATH-DISC-04 | B8: Foundations | C8: Flexible entry | D8: Fractions, Decimals and Percentages as One Family | E8: Complete | F8: Planned | G8: Planned | H8: Planned | I8: Planned | J8: Planned | K8: Not started | L8: Planned | M8: Sequence after spine review | N8: No live artifact linked | O8: GreenPrint v1.1 / map v0.2
A9: NEO-MATH-DISC-05 | B9: Foundations | C9: Flexible entry | D9: Patterns Before Letters | E9: Complete | F9: Planned | G9: Planned | H9: Planned | I9: Planned | J9: Planned | K9: Not started | L9: Planned | M9: Sequence after spine review | N9: No live artifact linked | O9: GreenPrint v1.1 / map v0.2
A10: NEO-MATH-DISC-06 | B10: Foundations | C10: Flexible entry | D10: Shape, Space and Measure Around Me | E10: Complete | F10: Planned | G10: Planned | H10: Planned | I10: Planned | J10: Planned | K10: Not started | L10: Planned | M10: Sequence after spine review | N10: No live artifact linked | O10: GreenPrint v1.1 / map v0.2
